Workbook

Sheet Октябр 2024
A1: Реализация | F1: Касса | I1: Баланс
A2: Число | B2: Модел | C2: Сони | D2: Нархи | E2: Сумма | F2: Число | G2: Сумма | I2: Остатка сумма Бозорда
A3: Остатка сумма олдинги | E3: ='Сентябр 2024'!I3 -> 22230000 | F3: 45566 | G3: =10800000+6250000 -> 17050000 | I3: =E199-G199 -> 74832000
A4: 45566 | B4: Тройка Болеро | C4: 96 | D4: 60000 | E4: =C4*D4 -> 5760000 | F4: 45567 | G4: =11000000+1800000 -> 12800000 | I4: курс | J4: 12750
B5: Тройка ромашка | C5: 126 | D5: 60000 | E5: =C5*D5 -> 7560000 | F5: 45568 | G5: 17920000 | H5: Разница | I5: =I3/J4 -> 5869.1765
A6: 45567 | B6: Тройка Болеро | C6: 58 | D6: 60000 | E6: =C6*D6 -> 3480000 | F6: 45569 | G6: 7700000 | I6: остатка товар. | J6: =ост.охири!F5 -> 35376000
B7: Тройка ромашка | C7: 44 | D7: 60000 | E7: =C7*D7 -> 2640000 | F7: 45570 | G7: 9200000
B8: Тройка Ўйинчоқ каш | C8: 84 | D8: 72000 | E8: =C8*D8 -> 6048000 | F8: 45571 | G8: =19250000+1500000 -> 20750000 | I8: Фарки | J8: =I3-J6 -> 39456000
B9: Нимча қиммати | C9: 74 | D9: 65000 | E9: =C9*D9 -> 4810000
B10: Тройка Мишка | C10: 92 | D10: 67000 | E10: =C10*D10 -> 6164000
A11: 45568 | B11: Тройка Ўйинчоқ каш | C11: 32 | D11: 72000 | E11: =C11*D11 -> 2304000 | I11: скидка
B12: Тройка ромашка | C12: 128 | D12: 60000 | E12: =C12*D12 -> 7680000
B13: Тройка Болеро | C13: 62 | D13: 60000 | E13: =C13*D13 -> 3720000
A14: 45569 | B14: Тройка Болеро | C14: 50 | D14: 60000 | E14: =C14*D14 -> 3000000
B15: Тройка Ўйинчоқ каш | C15: 18 | D15: 72000 | E15: =C15*D15 -> 1296000
B16: Тройка ромашка | C16: 62 | D16: 60000 | E16: =C16*D16 -> 3720000
B17: Тройка Ўйинчоқ каш | C17: 32 | D17: 72000 | E17: =C17*D17 -> 2304000
B18: Тройка Мишка | C18: 108 | D18: 67000 | E18: =C18*D18 -> 7236000
B19: Тройка ромашка | C19: 118 | D19: 60000 | E19: =C19*D19 -> 7080000
A20: 45571 | B20: Тройка Болеро | C20: 130 | D20: 60000 | E20: =C20*D20 -> 7800000
B21: Тройка Ўйинчоқ каш | C21: 72 | D21: 72000 | E21: =C21*D21 -> 5184000
B22: Тройка қуен кашмир | C22: 124 | D22: 75000 | E22: =C22*D22 -> 9300000
A23: 45573 | B23: Двойка мишка қуен | C23: 36 | D23: 63000 | E23: =C23*D23 -> 2268000
B24: Тройка Болеро | C24: 24 | D24: 60000 | E24: =C24*D24 -> 1440000
B25: Двойка капишон | C25: 32 | D25: 62000 | E25: =C25*D25 -> 1984000
B26: Ромашка Қалин | C26: 48 | D26: 65000 | E26: =C26*D26 -> 3120000
B27: Тройка қуен кашмир | C27: 50 | D27: 75000 | E27: =C27*D27 -> 3750000
A28: 45574 | B28: Ромашка Нимча | C28: 62 | D28: 75000 | E28: =C28*D28 -> 4650000
B29: Двойка мишка қуен | C29: 72 | D29: 63000 | E29: =C29*D29 -> 4536000
B30: Ромашка Қалин | C30: 96 | D30: 65000 | E30: =C30*D30 -> 6240000
A31: 45575 | B31: Ромашка Қалин | C31: 120 | D31: 65000 | E31: =C31*D31 -> 7800000
B32: Ромашка Нимча | C32: 16 | D32: 75000 | E32: =C32*D32 -> 1200000
B33: Двойка капишон | C33: 54 | D33: 62000 | E33: =C33*D33 -> 3348000
B34: Тройка ромашка | C34: 10 | D34: 60000 | E34: =C34*D34 -> 600000
E35: =C35*D35 -> 0
E36: =C36*D36 -> 0
E37: =C37*D37 -> 0
E38: =C38*D38 -> 0
E39: =C39*D39 -> 0
E40: =C40*D40 -> 0
...

Sheet ост.охири
A2: Модел | B2: Сони | C2: Нархи | D2: Сумма
A3: Тройка қалин | B3: 4 | C3: 50000 | D3: =B3*C3 -> 200000 | E3: об.берилган | F3: ='Май 2024'!I3 -> 54686000
A4: Нимча арзони | B4: 3 | C4: 62000 | D4: =B4*C4 -> 186000
A5: Адидас | B5: 18 | C5: 30000 | D5: =B5*C5 -> 540000 | E5: об.остатка | F5: =D39 -> 35376000
A6: Тройка динозавр | B6: 48 | C6: 50000 | D6: =B6*C6 -> 2400000
A7: Бухоро вил нимча | B7: 12 | C7: 57000 | D7: =B7*C7 -> 684000
A8: Тройка ромбик | B8: 2 | C8: 56000 | D8: =B8*C8 -> 112000 | E8: разница | F8: =F3-F5 -> 19310000
A9: Беар комплект | B9: 38 | C9: 41000 | D9: =B9*C9 -> 1558000
A10: Тройка микки | B10: 10 | C10: 52000 | D10: =B10*C10 -> 520000
A11: Тройка айиқ | B11: 8 | C11: 55000 | D11: =B11*C11 -> 440000
A12: Қиз гул | B12: 56 | C12: 44000 | D12: =B12*C12 -> 2464000
A13: Тройка Ўйинчоқ кашмир | B13: 30 | C13: 72000 | D13: =B13*C13 -> 2160000
A14: Тройка Ромашка болеро | B14: 96 | C14: 60000 | D14: =B14*C14 -> 5760000
A15: Двойка микки | B15: 36 | C15: 42000 | D15: =B15*C15 -> 1512000
A16: Ўйинчоқ | B16: 2 | C16: 45000 | D16: =B16*C16 -> 90000
A17: Тоника ободог | B17: 70 | C17: 37000 | D17: =B17*C17 -> 2590000
A18: Полестр | B18: 4 | C18: 40000 | D18: =B18*C18 -> 160000
A19: Двойка виливет | B19: 82 | C19: 40000 | D19: =B19*C19 -> 3280000
A20: Тройка мишка | B20: 110 | C20: 67000 | D20: =B20*C20 -> 7370000
A21: Нимча қиммати | B21: 10 | C21: 65000 | D21: =B21*C21 -> 650000
A22: Тройка қуен кашмир | B22: =16+20 -> 36 | C22: 75000 | D22: =B22*C22 -> 2700000
D23: =B23*C23 -> 0
D24: =B24*C24 -> 0
D25: =B25*C25 -> 0
D26: =B26*C26 -> 0
D27: =B27*C27 -> 0
D28: =B28*C28 -> 0
D29: =B29*C29 -> 0
A30: Қарздорлар
A31: Самара
A32: Илхом
A33: Муқаддас опа
A34: зафар
A35: Муқбира
A36: Бобур
A37: Улуғбек
A38: доначи
D39: =SUM(D3:D38) -> 35376000
D206: 41415000

Sheet Сентябр 2024
A1: Реализация | F1: Касса | I1: Баланс
A2: Число | B2: Модел | C2: Сони | D2: Нархи | E2: Сумма | F2: Число | G2: Сумма | I2: Остатка сумма Бозорда
A3: Остатка сумма олдинги | E3: ='Июл 2024'!I3 -> 28637000 | F3: 45536 | G3: 5300000 | I3: =E199-G199 -> 22230000
A4: 45536 | B4: Тройка ромашка | C4: 88 | D4: 60000 | E4: =C4*D4 -> 5280000 | F4: 45538 | G4: =4432000+1270000+1300000+7600000 -> 14602000 | I4: курс | J4: 12750
A5: 45538 | B5: Тройка ромашка | C5: 82 | D5: 60000 | E5: =C5*D5 -> 4920000 | F5: 45538 | G5: 536000 | H5: Разница | I5: =I3/J4 -> 1743.5294
B6: Нимча қиммати | C6: 86 | D6: 65000 | E6: =C6*D6 -> 5590000 | F6: 45539 | G6: =6720000+9100000 -> 15820000 | I6: остатка товар. | J6: =ост.охири!F5 -> 35376000
B7: Нимча плашевка | C7: 34 | D7: 62000 | E7: =C7*D7 -> 2108000 | F7: 45540 | G7: 12650000
A8: 45539 | B8: Нимча қиммати | C8: 60 | D8: 65000 | E8: =C8*D8 -> 3900000 | F8: 45541 | G8: 17825000 | I8: Фарки | J8: =I3-J6 -> -13146000
B9: Нимча плашевка | C9: 14 | D9: 62000 | E9: =C9*D9 -> 868000 | F9: 45542 | G9: 16000000
B10: Тройка ромашка | C10: 120 | D10: 60000 | E10: =C10*D10 -> 7200000 | F10: 45543 | G10: 12420000
A11: 45540 | B11: Нимча қиммати | C11: 68 | D11: 65000 | E11: =C11*D11 -> 4420000 | F11: 45545 | G11: 13175000 | I11: скидка
B12: Тройка ромашка | C12: 82 | D12: 60000 | E12: =C12*D12 -> 4920000 | F12: 45546 | G12: 14350000
B13: Микки двойка | C13: 50 | D13: 42000 | E13: =C13*D13 -> 2100000 | F13: 45547 | G13: 10960000
A14: 45541 | B14: Тройка ромашка | C14: 124 | D14: 60000 | E14: =C14*D14 -> 7440000 | F14: 45548 | G14: =190000+11350000 -> 11540000
B15: Нимча қиммати | C15: 68 | D15: 65000 | E15: =C15*D15 -> 4420000 | F15: 45549 | G15: 16350000
B16: Остаткалар | C16: =34*40000+8*50000+24*40000+24*50000+12*40000+14*40000+10*45000+6*40000+6*41000+2*50000+2*40000 -> 6076000 | D16: 1 | E16: =C16*D16 -> 6076000 | F16: 45550 | G16: 15085000
A17: 45542 | B17: Тройка ромашка | C17: 120 | D17: 60000 | E17: =C17*D17 -> 7200000 | F17: 45552 | G17: =9800000+200000 -> 10000000
A18: 45543 | B18: Тройка ромашка | C18: 80 | D18: 60000 | E18: =C18*D18 -> 4800000 | F18: 45553 | G18: 10120000
B19: Нимча плашевка | C19: 110 | D19: 62000 | E19: =C19*D19 -> 6820000 | F19: 45554 | G19: 12455000
B20: Нимча қиммати | C20: 112 | D20: 65000 | E20: =C20*D20 -> 7280000 | F20: 45555 | G20: 11720000
A21: 45545 | B21: Тройка ромашка | C21: 74 | D21: 60000 | E21: =C21*D21 -> 4440000 | F21: 45556 | G21: 9760000
B22: Нимча қиммати | C22: 84 | D22: 65000 | E22: =C22*D22 -> 5460000 | F22: 45557 | G22: 14207000
B23: Нимча плашевка | C23: 14 | D23: 62000 | E23: =C23*D23 -> 868000 | F23: 45559 | G23: 21000000
A24: 45546 | B24: Нимча қиммати | C24: 54 | D24: 65000 | E24: =C24*D24 -> 3510000 | F24: 45560 | G24: 12500000
B25: Нимча плашевка | C25: 52 | D25: 62000 | E25: =C25*D25 -> 3224000 | F25: 45561 | G25: 20450000
B26: Тройка ромашка | C26: 110 | D26: 60000 | E26: =C26*D26 -> 6600000 | F26: 45562 | G26: 11360000
A27: 45547 | B27: Микки двойка | C27: 72 | D27: 42000 | E27: =C27*D27 -> 3024000 | F27: 45563 | G27: 7350000
B28: Нимча қиммати | C28: 80 | D28: 65000 | E28: =C28*D28 -> 5200000 | F28: 45564 | G28: 17640000
B29: Тройка ромашка | C29: 74 | D29: 60000 | E29: =C29*D29 -> 4440000
A30: 45548 | B30: Нимча қиммати | C30: 50 | D30: 65000 | E30: =C30*D30 -> 3250000
B31: Тройка ромашка | C31: 150 | D31: 60000 | E31: =C31*D31 -> 9000000
A32: 45549 | B32: Тройка ромашка | C32: 106 | D32: 60000 | E32: =C32*D32 -> 6360000
B33: Нимча қиммати | C33: 92 | D33: 65000 | E33: =C33*D33 -> 5980000
A34: 45550 | B34: Нимча қиммати | C34: 58 | D34: 65000 | E34: =C34*D34 -> 3770000
B35: Тройка ромашка | C35: 252 | D35: 60000 | E35: =C35*D35 -> 15120000
A36: 45552 | B36: Тройка ромашка | C36: 128 | D36: 60000 | E36: =C36*D36 -> 7680000
B37: Нимча қиммати | C37: 44 | D37: 65000 | E37: =C37*D37 -> 2860000
A38: 45553 | B38: Тройка ромашка | C38: 190 | D38: 60000 | E38: =C38*D38 -> 11400000
A39: 45554 | B39: Тройка ромашка | C39: 192 | D39: 60000 | E39: =C39*D39 -> 11520000
A40: 45555 | B40: Нимча қиммати | C40: 90 | D40: 65000 | E40: =C40*D40 -> 5850000
...

Sheet Июл 2024
A1: Реализация | F1: Касса | I1: Баланс
A2: Число | B2: Модел | C2: Сони | D2: Нархи | E2: Сумма | F2: Число | G2: Сумма | I2: Остатка сумма Бозорда
A3: Остатка сумма олдинги | E3: ='Май 2024'!I3 -> 54686000 | F3: 45475 | G3: 9210000 | I3: =E199-G199 -> 28637000
A4: 45476 | B4: Бухоро | C4: 60 | D4: 47000 | E4: =C4*D4 -> 2820000 | F4: 45476 | G4: 3000000 | I4: курс | J4: 12750
A5: 45480 | B5: Двойка муслин | C5: 56 | D5: 40000 | E5: =C5*D5 -> 2240000 | F5: 45477 | G5: 7950000 | I5: =I3/J4 -> 2246.0392
B6: Горох | C6: 90 | D6: 40000 | E6: =C6*D6 -> 3600000 | F6: 45478 | G6: 2185000 | I6: остатка товар. | J6: =ост.охири!F5 -> 35376000
B7: Бухоро | C7: 80 | D7: 47000 | E7: =C7*D7 -> 3760000 | F7: 45480 | G7: 1810000
B8: Трусили | C8: 4 | D8: 40000 | E8: =C8*D8 -> 160000 | F8: 45482 | G8: 3850000 | I8: Фарки | J8: =I3-J6 -> -6739000
A9: 45482 | B9: Бухоро | C9: 80 | D9: 47000 | E9: =C9*D9 -> 3760000 | F9: 45483 | G9: 3450000
A10: 45484 | B10: Горох лямка | C10: 124 | D10: 40000 | E10: =C10*D10 -> 4960000 | F10: 45484 | G10: 10360000
A11: 45487 | B11: Қиз гул | C11: 120 | D11: 44000 | E11: =C11*D11 -> 5280000 | F11: 45485 | G11: 2250000 | I11: скидка
A12: 45489 | B12: Двойка микки | C12: 200 | D12: 42000 | E12: =C12*D12 -> 8400000 | F12: 45486 | G12: 700000
A13: 45490 | B13: Тройка микки | C13: 36 | D13: 52000 | E13: =C13*D13 -> 1872000 | F13: 45487 | G13: 4460000
A14: 45491 | B14: Тройка микки | C14: 162 | D14: 52000 | E14: =C14*D14 -> 8424000 | F14: 45489 | G14: 3400000
A15: 45492 | B15: Двойка микки | C15: 150 | D15: 42000 | E15: =C15*D15 -> 6300000 | F15: 45490 | G15: 12450000
B16: Тройка микки | C16: 24 | D16: 52000 | E16: =C16*D16 -> 1248000 | F16: 45491 | G16: 9700000
A17: 45493 | B17: Тройка микки | C17: 98 | D17: 52000 | E17: =C17*D17 -> 5096000 | F17: 45492 | G17: 3200000
B18: Двойка микки | C18: 48 | D18: 42000 | E18: =C18*D18 -> 2016000 | F18: 45493 | G18: 9050000
A19: 45494 | B19: Тройка микки | C19: 130 | D19: 52000 | E19: =C19*D19 -> 6760000 | F19: 45494 | G19: 12760000
B20: Двойка микки | C20: 106 | D20: 42000 | E20: =C20*D20 -> 4452000 | F20: 45496 | G20: 9550000
A21: 45496 | B21: Двойка микки | C21: 80 | D21: 42000 | E21: =C21*D21 -> 3360000 | F21: 45497 | G21: 7000000
B22: Тройка микки | C22: 74 | D22: 52000 | E22: =C22*D22 -> 3848000 | F22: 45498 | G22: 14900000
B23: Стар двойка | C23: 118 | D23: 45000 | E23: =C23*D23 -> 5310000 | F23: 45499 | G23: 8050000
B24: Юлдуз тройка | C24: 76 | D24: 55000 | E24: =C24*D24 -> 4180000 | F24: 45500 | G24: 5700000
A25: 45497 | B25: Двойка микки | C25: 196 | D25: 42000 | E25: =C25*D25 -> 8232000 | F25: 45501 | G25: 9740000
B26: Тройка қуен | C26: 18 | D26: 50000 | E26: =C26*D26 -> 900000 | F26: 45503 | G26: 8550000
B27: Воолд | C27: 30 | D27: 50000 | E27: =C27*D27 -> 1500000 | F27: 45504 | G27: 2350000
B28: Полоска айиқ | C28: 12 | D28: 40000 | E28: =C28*D28 -> 480000 | F28: 45505 | G28: 4800000
B29: Айиқ двойка | C29: 24 | D29: 40000 | E29: =C29*D29 -> 960000 | F29: 45506 | G29: 7900000
B30: Панда двойка полоска | C30: 90 | D30: 40000 | E30: =C30*D30 -> 3600000 | F30: 45507 | G30: 970000
A31: 45498 | B31: Тройка микки | C31: 128 | D31: 52000 | E31: =C31*D31 -> 6656000 | F31: Возврат | G31: 22721000 | H31: Ёзгила
B32: Двойка микки | C32: 42 | D32: 42000 | E32: =C32*D32 -> 1764000 | F32: 45508 | G32: 11680000
A33: 45499 | B33: Тройка микки | C33: 86 | D33: 52000 | E33: =C33*D33 -> 4472000 | F33: 45510 | G33: 4600000
A34: 45500 | B34: Тройка микки | C34: 112 | D34: 52000 | E34: =C34*D34 -> 5824000 | F34: 45511 | G34: 600000
B35: Двойка микки | C35: 70 | D35: 42000 | E35: =C35*D35 -> 2940000 | F35: 45512 | G35: 14600000
A36: 45501 | B36: Тройка микки | C36: 56 | D36: 52000 | E36: =C36*D36 -> 2912000 | F36: 45513 | G36: 400000
B37: Двойка микки | C37: 100 | D37: 42000 | E37: =C37*D37 -> 4200000 | F37: 45514 | G37: 3350000
A38: 45503 | B38: Двойка микки | C38: 110 | D38: 42000 | E38: =C38*D38 -> 4620000 | F38: 45515 | G38: =1270000+3375000 -> 4645000
B39: Тройка микки | C39: 84 | D39: 52000 | E39: =C39*D39 -> 4368000 | F39: 45517 | G39: 3130000
B40: Тройка динозавр | C40: 120 | D40: 50000 | E40: =C40*D40 -> 6000000 | F40: 45518 | G40: 3900000
...

Sheet Май 2024
A1: Реализация | F1: Касса | I1: Баланс
A2: Число | B2: Модел | C2: Сони | D2: Нархи | E2: Сумма | F2: Число | G2: Сумма | I2: Остатка сумма Бозорда
A3: Остатка сумма олдинги | E3: ='Январ 2024'!I3 -> 16871000 | F3: 45413 | G3: 8000000 | I3: =E199-G199 -> 54686000
A4: 45413 | B4: Муслим ўғил | C4: 56 | D4: 43000 | E4: =C4*D4 -> 2408000 | F4: 45414 | G4: 3000000 | I4: курс | J4: 12750
B5: Лион двойка лондон | C5: 126 | D5: 47000 | E5: =C5*D5 -> 5922000 | F5: 45415 | G5: =13000000+635000 -> 13635000 | I5: =I3/J4 -> 4289.098
B6: Кўйлак полоска | C6: 84 | D6: 42000 | E6: =C6*D6 -> 3528000 | F6: 45416 | G6: 5700000 | I6: остатка товар. | J6: =ост.охири!F5 -> 35376000
B7: Лямка двойка | C7: 144 | D7: 40000 | E7: =C7*D7 -> 5760000 | F7: 45417 | G7: 5730000
B8: Динозавр двойка | C8: 8 | D8: 40000 | E8: =C8*D8 -> 320000 | F8: 45419 | G8: 8200000 | I8: Фарки | J8: =I3-J6 -> 19310000
B9: Полоска тройка лион | C9: 8 | D9: 56000 | E9: =C9*D9 -> 448000 | F9: 45420 | G9: 13000000
A10: 45414 | B10: Муслим ўғил | C10: 106 | D10: 43000 | E10: =C10*D10 -> 4558000 | F10: 45421 | G10: 7100000
B11: Тройка труси | C11: 102 | D11: 45000 | E11: =C11*D11 -> 4590000 | F11: 45422 | G11: 5000000 | I11: скидка
B12: Лион двойка лондон | C12: 70 | D12: 47000 | E12: =C12*D12 -> 3290000 | F12: 45423 | G12: 8100000
B13: Ғижим лион | C13: 82 | D13: 45000 | E13: =C13*D13 -> 3690000 | F13: 45424 | G13: 13170000
A14: 45415 | B14: Динозавр двойка | C14: 80 | D14: 38000 | E14: =C14*D14 -> 3040000 | F14: 45426 | G14: 6000000
B15: Муслим ўғил | C15: 44 | D15: 43000 | E15: =C15*D15 -> 1892000 | F15: 45427 | G15: 3550000
B16: Ғижим лион | C16: 86 | D16: 45000 | E16: =C16*D16 -> 3870000 | F16: 45428 | G16: 8311000
A17: 45416 | B17: Динозавр двойка | C17: 60 | D17: 38000 | E17: =C17*D17 -> 2280000 | F17: 45429 | G17: 10250000
B18: Кофта юбка | C18: 30 | D18: 48000 | E18: =C18*D18 -> 1440000 | F18: 45430 | G18: 12000000
B19: Лион двойка лондон | C19: 180 | D19: 47000 | E19: =C19*D19 -> 8460000 | F19: 45431 | G19: 7745000
A20: 45417 | B20: Кофта юбка | C20: 104 | D20: 48000 | E20: =C20*D20 -> 4992000 | F20: 45433 | G20: 10350000
B21: Тройка труси | C21: 100 | D21: 45000 | E21: =C21*D21 -> 4500000 | F21: 45434 | G21: 11200000
B22: Лион двойка лондон | C22: 16 | D22: 47000 | E22: =C22*D22 -> 752000 | F22: 45435 | G22: 4150000
B23: Капишон муслим | C23: 72 | D23: 46000 | E23: =C23*D23 -> 3312000 | F23: 45436 | G23: 2400000
B24: Қиз жинси ободог | C24: 90 | D24: 45000 | E24: =C24*D24 -> 4050000 | F24: 45437 | G24: 2000000
A25: 45420 | B25: Полоска тройка лион | C25: 30 | D25: 56000 | E25: =C25*D25 -> 1680000 | F25: 45438 | G25: 4700000
B26: Кўйлак шортик барг | C26: 124 | D26: 43000 | E26: =C26*D26 -> 5332000 | F26: 45440 | G26: 9600000
B27: Динозавр двойка | C27: 40 | D27: 38000 | E27: =C27*D27 -> 1520000 | F27: 45441 | G27: 4650000
A28: 45421 | B28: Муслим ўғил | C28: 100 | D28: 43000 | E28: =C28*D28 -> 4300000 | F28: 45442 | G28: 9300000
B29: Динозавр двойка | C29: 40 | D29: 38000 | E29: =C29*D29 -> 1520000 | F29: 45443 | G29: 2000000
B30: Полоска тройка лион | C30: 18 | D30: 56000 | E30: =C30*D30 -> 1008000 | F30: 45444 | G30: 5200000
A31: 45422 | B31: Муслим ўғил | C31: 52 | D31: 43000 | E31: =C31*D31 -> 2236000 | F31: Скидка | G31: 4432000
A32: 45423 | B32: Тройка бухоро | C32: 20 | D32: 52000 | E32: =C32*D32 -> 1040000 | F32: 45445 | G32: 4750000
B33: Динозавр двойка | C33: 76 | D33: 38000 | E33: =C33*D33 -> 2888000 | F33: 45447 | G33: 11250000
B34: Капишон муслим | C34: 60 | D34: 46000 | E34: =C34*D34 -> 2760000 | F34: 45448 | G34: 9650000
B35: Муслим ўғил | C35: 102 | D35: 43000 | E35: =C35*D35 -> 4386000 | F35: 45449 | G35: 11155000
A36: 45424 | B36: Капишон муслим | C36: 136 | D36: 46000 | E36: =C36*D36 -> 6256000 | F36: 45450 | G36: 2800000
B37: Муслим ўғил | C37: 48 | D37: 43000 | E37: =C37*D37 -> 2064000 | F37: 45451 | G37: 13900000
A38: 45426 | B38: Тройка бухоро | C38: 58 | D38: 52000 | E38: =C38*D38 -> 3016000 | F38: Гипюр мус | G38: =216*12000 -> 2592000
B39: Капишон муслим | C39: 112 | D39: 46000 | E39: =C39*D39 -> 5152000 | F39: 45452 | G39: 16465000
B40: Барг двойка | C40: 56 | D40: 43000 | E40: =C40*D40 -> 2408000 | F40: 45454 | G40: 10500000
...

Sheet Январ 2024
A1: Реализация | F1: Касса | I1: Баланс
A2: Число | B2: Модел | C2: Сони | D2: Нархи | E2: Сумма | F2: Число | G2: Сумма | I2: Остатка сумма Бозорда
A3: Остатка сумма олдинги | E3: ='2023 сентябр'!I3 -> 34995000 | F3: 45294 | G3: 1610000 | I3: =E199-G199 -> 16871000
A4: 45295 | B4: Динозавр тройка | C4: 112 | D4: 67000 | E4: =C4*D4 -> 7504000 | F4: 45295 | G4: 6600000 | I4: курс | J4: 11550
A5: 45296 | B5: Водаласка двойка | C5: 180 | D5: 39000 | E5: =C5*D5 -> 7020000 | F5: 45296 | G5: 6300000 | I5: =I3/J4 -> 1460.6926
A6: 45297 | B6: Винни пух кашмир | C6: 12 | D6: 52000 | E6: =C6*D6 -> 624000 | F6: 45297 | G6: 5600000 | I6: остатка товар. | J6: =ост.охири!F5 -> 35376000
B7: Винни пух почка | C7: 108 | D7: 40000 | E7: =C7*D7 -> 4320000 | F7: 45298 | G7: 16520000
A8: 45298 | B8: Динозавр тройка | C8: 160 | D8: 67000 | E8: =C8*D8 -> 10720000 | F8: 45300 | G8: 10000000 | I8: Фарки | J8: =I3-J6 -> -18505000
A9: 45300 | B9: Қуен тройка | C9: 80 | D9: 55000 | E9: =C9*D9 -> 4400000 | F9: 45301 | G9: 3750000
B10: Динозавр тройка | C10: 64 | D10: 67000 | E10: =C10*D10 -> 4288000 | F10: 45302 | G10: 14700000
A11: 45301 | B11: Қуен тройка | C11: 98 | D11: 55000 | E11: =C11*D11 -> 5390000 | F11: 45303 | G11: 8100000 | I11: скидка
B12: Динозавр тройка | C12: 44 | D12: 67000 | E12: =C12*D12 -> 2948000 | F12: 45304 | G12: 7660000
A13: 45302 | B13: Мишка тройка хб | C13: 172 | D13: 60000 | E13: =C13*D13 -> 10320000 | F13: 45305 | G13: 8600000
B14: Динозавр тройка | C14: 40 | D14: 67000 | E14: =C14*D14 -> 2680000 | F14: 45307 | G14: 12762000
A15: 45303 | B15: Қуен тройка | C15: 150 | D15: 55000 | E15: =C15*D15 -> 8250000 | F15: 45308 | G15: 4150000
B16: Мишка тр қалин | C16: 10 | D16: 72000 | E16: =C16*D16 -> 720000 | F16: 45309 | G16: 11830000
A17: 45304 | B17: Қуен тройка | C17: 48 | D17: 55000 | E17: =C17*D17 -> 2640000 | F17: 45310 | G17: 8250000
B18: Мишка тройка хб | C18: 120 | D18: 60000 | E18: =C18*D18 -> 7200000 | F18: 45311 | G18: 6500000
A19: 45305 | B19: Мишка тройка хб | C19: 100 | D19: 60000 | E19: =C19*D19 -> 6000000 | F19: 45312 | G19: 11785000
B20: Қуен тройка | C20: 52 | D20: 55000 | E20: =C20*D20 -> 2860000 | F20: 45314 | G20: =2400000+3480000 -> 5880000
B21: Винни пух почка | C21: 38 | D21: 40000 | E21: =C21*D21 -> 1520000 | F21: 45315 | G21: =4900000+2160000 -> 7060000
A22: 45307 | B22: Панда хб | C22: 100 | D22: 44000 | E22: =C22*D22 -> 4400000 | F22: 45316 | G22: 2850000
B23: Мишка тройка хб | C23: 92 | D23: 60000 | E23: =C23*D23 -> 5520000 | F23: 45317 | G23: 1300000
B24: Мишка тр қалин | C24: 4 | D24: 72000 | E24: =C24*D24 -> 288000 | F24: 45318 | G24: 550000
A25: 45308 | B25: Панда хб | C25: 176 | D25: 44000 | E25: =C25*D25 -> 7744000 | F25: 45319 | G25: 3083000
B26: Мишка тройка хб | C26: 36 | D26: 60000 | E26: =C26*D26 -> 2160000 | F26: 45319 | G26: 9416000 | H26: Возврат
A27: 45309 | B27: Қуен тройка | C27: 120 | D27: 55000 | E27: =C27*D27 -> 6600000 | F27: 45321 | G27: 6450000
A28: 45310 | B28: Қиз тройка | C28: 84 | D28: 60000 | E28: =C28*D28 -> 5040000 | F28: 45322 | G28: 5000000
A29: 45311 | B29: Кўйлак ободог | C29: 64 | D29: 50000 | E29: =C29*D29 -> 3200000 | F29: 45323 | G29: 1425000
B30: Мишка тройка хб | C30: 168 | D30: 60000 | E30: =C30*D30 -> 10080000 | F30: 45324 | G30: =500000+745000 -> 1245000
A31: 45312 | B31: Қиз тройка | C31: 156 | D31: 60000 | E31: =C31*D31 -> 9360000 | F31: 45326 | G31: 1217000
A32: 45314 | B32: Қиз тройка | C32: 40 | D32: 60000 | E32: =C32*D32 -> 2400000 | F32: 45328 | G32: 1850000
A33: 45315 | B33: Қиз тройка | C33: 68 | D33: 60000 | E33: =C33*D33 -> 4080000 | F33: 45329 | G33: 110000
B34: Кўйлак ободог | C34: 20 | D34: 50000 | E34: =C34*D34 -> 1000000 | F34: 45330 | G34: 3700000
B35: Тр мишка енги | C35: 70 | D35: 64000 | E35: =C35*D35 -> 4480000 | F35: 45331 | G35: 6300000
A36: 45316 | B36: Қуен тройка | C36: 98 | D36: 55000 | E36: =C36*D36 -> 5390000 | F36: 45332 | G36: 2520000
B37: Панда хб | C37: 96 | D37: 44000 | E37: =C37*D37 -> 4224000 | F37: 45333 | G37: 4710000
B38: Адидас двойка | C38: 48 | D38: 40000 | E38: =C38*D38 -> 1920000 | F38: 45335 | G38: 7000000
A39: 45317 | B39: Кўйлак ободог | C39: 66 | D39: 50000 | E39: =C39*D39 -> 3300000 | F39: 45336 | G39: 10120000
A40: 45319 | B40: Кўйлак ободог | C40: 96 | D40: 50000 | E40: =C40*D40 -> 4800000 | F40: 45337 | G40: 17200000
...

Sheet Баланс 2024
A2: Об.бозорга берилган махсулот | B2: ='Январ 2024'!E199 -> 758293000
A3: Об. Олинган кассалар | B3: ='Январ 2024'!G199 -> 741422000

Sheet 2023 сентябр
A1: Реализация | F1: Касса | I1: Баланс
A2: Число | B2: Модел | C2: Сони | D2: Нархи | E2: Сумма | F2: Число | G2: Сумма | I2: Остатка сумма Бозорда
A3: Остатка сумма олдинги | E3: ='2023 август'!I3 -> 15112000 | F3: 45170 | G3: 1800000 | I3: =E199-G199 -> 34995000
A4: 45170 | B4: Адидас спортивка | C4: 12 | D4: 45000 | E4: =C4*D4 -> 540000 | F4: 45171 | G4: 150000 | I4: курс | J4: 11550
A5: 45174 | B5: Бамбук микки | C5: 190 | D5: 38000 | E5: =C5*D5 -> 7220000 | F5: 45172 | G5: 965000 | I5: =I3/J4 -> 3029.8701
A6: 45175 | B6: Вил ромашка | C6: 11 | D6: 35000 | E6: =C6*D6 -> 385000 | F6: 45174 | G6: 3000000 | I6: остатка товар.
A7: 45176 | B7: Бамбук микки | C7: 140 | D7: 38000 | E7: =C7*D7 -> 5320000 | F7: 45175 | G7: 5600000
A8: 45177 | B8: Бамбук микки | C8: 28 | D8: 38000 | E8: =C8*D8 -> 1064000 | F8: 45176 | G8: 6000000 | I8: Фарки | J8: =I3-J6 -> 34995000
A9: 45179 | B9: Бамбук микки | C9: 100 | D9: 38000 | E9: =C9*D9 -> 3800000 | F9: 45177 | G9: 175000
A10: 45181 | B10: Бамбук микки | C10: 100 | D10: 38000 | E10: =C10*D10 -> 3800000 | F10: 45179 | G10: 2385000
A11: 45183 | B11: Бамбук микки | C11: 142 | D11: 38000 | E11: =C11*D11 -> 5396000 | F11: 45181 | G11: 4500000 | I11: скидка
A12: 45184 | B12: Бамбук микки | C12: 90 | D12: 38000 | E12: =C12*D12 -> 3420000 | F12: 45182 | G12: 950000
A13: 45185 | B13: Беар қалин | C13: 102 | D13: 60000 | E13: =C13*D13 -> 6120000 | F13: 45183 | G13: 6600000
A14: 45185 | B14: Бамбук микки | C14: 198 | D14: 38000 | E14: =C14*D14 -> 7524000 | F14: 45184 | G14: 5900000
A15: 45186 | B15: Бамбук микки | C15: 110 | D15: 38000 | E15: =C15*D15 -> 4180000 | F15: 45185 | G15: 4100000
A16: 45188 | B16: Барби кашмир | C16: 174 | D16: 53000 | E16: =C16*D16 -> 9222000 | F16: 45186 | G16: 3454000
B17: Беар қалин | C17: 122 | D17: 60000 | E17: =C17*D17 -> 7320000 | F17: 45188 | G17: =2550000+8950000+1220000 -> 12720000
B18: Виливет двойка | C18: 6 | D18: 50000 | E18: =C18*D18 -> 300000 | F18: 45189 | G18: 4400000
B19: Бамбук микки | C19: 106 | D19: 38000 | E19: =C19*D19 -> 4028000 | F19: 45190 | G19: 6700000
A20: 45189 | B20: Барби кашмир | C20: 110 | D20: 53000 | E20: =C20*D20 -> 5830000 | F20: 45191 | G20: 5900000
B21: Беар қалин | C21: 120 | D21: 60000 | E21: =C21*D21 -> 7200000 | F21: 45192 | G21: 6260000
B22: Барби кашмир | C22: 10 | D22: 53000 | E22: =C22*D22 -> 530000 | F22: 45193 | G22: 8655000 | H22: Возврат
B23: Бамбук микки | C23: 12 | D23: 38000 | E23: =C23*D23 -> 456000 | F23: 45193 | G23: =435000+4650000 -> 5085000
A24: 45191 | B24: Беар қалин | C24: 124 | D24: 60000 | E24: =C24*D24 -> 7440000 | F24: 45195 | G24: =9750000+480000 -> 10230000
A25: 45192 | B25: Двойва луис виттон | C25: 118 | D25: 60000 | E25: =C25*D25 -> 7080000 | F25: 45196 | G25: 8850000
A26: 45193 | B26: Двойва луис виттон | C26: 32 | D26: 60000 | E26: =C26*D26 -> 1920000 | F26: 45197 | G26: 350000
B27: Барби кашмир | C27: 55 | D27: 53000 | E27: =C27*D27 -> 2915000 | F27: 45198 | G27: 2400000
B28: Беар қалин | C28: 72 | D28: 60000 | E28: =C28*D28 -> 4320000 | F28: 45199 | G28: 650000
A29: 45195 | B29: Мини мода кашмир | C29: 122 | D29: 58000 | E29: =C29*D29 -> 7076000 | F29: 45200 | G29: 11767000
B30: Беар қалин | C30: 22 | D30: 60000 | E30: =C30*D30 -> 1320000 | F30: 45202 | G30: 2415000
A31: 45196 | B31: Беар қалин | C31: 8 | D31: 60000 | E31: =C31*D31 -> 480000 | F31: 45203 | G31: 350000
B32: Барби кашмир | C32: 2 | D32: 53000 | E32: =C32*D32 -> 106000 | F32: 45204 | G32: 13800000
B33: Мини мода кашмир | C33: 36 | D33: 58000 | E33: =C33*D33 -> 2088000 | F33: 45205 | G33: 4200000
A34: 45199 | B34: Ўғил қиз беар | C34: 306 | D34: 54000 | E34: =C34*D34 -> 16524000 | F34: 45206 | G34: 1700000
A35: 45200 | B35: Ўғил қиз беар | C35: 38 | D35: 54000 | E35: =C35*D35 -> 2052000 | F35: 45207 | G35: 7330000
A36: 45203 | B36: Ўғил қиз беар | C36: 140 | D36: 54000 | E36: =C36*D36 -> 7560000 | F36: 45209 | G36: 9500000
A37: 45204 | B37: Мини мода кашмир | C37: 88 | D37: 58000 | E37: =C37*D37 -> 5104000 | F37: 45210 | G37: 2550000
A38: 45205 | B38: Мини мода кашмир | C38: 84 | D38: 58000 | E38: =C38*D38 -> 4872000 | F38: 45211 | G38: 14000000
A39: 45207 | B39: Ўғил қиз беар | C39: 70 | D39: 54000 | E39: =C39*D39 -> 3780000 | F39: 45212 | G39: 1090000
A40: 45209 | B40: Ўғил қиз беар | C40: 152 | D40: 54000 | E40: =C40*D40 -> 8208000 | F40: 45214 | G40: 7930000
...

Sheet 2023 август
A1: Реализация | F1: Касса | I1: Баланс
A2: Число | B2: Модел | C2: Сони | D2: Нархи | E2: Сумма | F2: Число | G2: Сумма | I2: Остатка сумма Бозорда
A3: Остатка сумма олдинги | E3: ='2023 июл'!I3 -> 37556000 | F3: 45139 | G3: 4750000 | I3: =E199-G199 -> 15112000
A4: 45140 | B4: Виливет двойка | C4: 48 | D4: 50000 | E4: =C4*D4 -> 2400000 | F4: 45140 | G4: 1600000 | I4: курс | J4: 11550
A5: 45141 | B5: Гуччи двойка | C5: 92 | D5: 46000 | E5: =C5*D5 -> 4232000 | F5: 45141 | G5: 8500000 | I5: =I3/J4 -> 1308.3983
A6: 45141 | B6: Панда полестр | C6: 22 | D6: 39000 | E6: =C6*D6 -> 858000 | F6: 45142 | G6: 1760000 | I6: остатка товар. | J6: =ост.охири!F5 -> 35376000
A7: 45142 | B7: Виливет двойка | C7: 80 | D7: 50000 | E7: =C7*D7 -> 4000000 | F7: 45143 | G7: 4200000
A8: 45142 | B8: Айиқ полоска | C8: 20 | D8: 40000 | E8: =C8*D8 -> 800000 | F8: 45144 | G8: 2944000 | I8: Фарки | J8: =I3-J6 -> -20264000
A9: 45143 | B9: Виливет двойка | C9: 52 | D9: 50000 | E9: =C9*D9 -> 2600000 | F9: 45146 | G9: 1000000
A10: 45144 | B10: Виливет двойка | C10: 64 | D10: 50000 | E10: =C10*D10 -> 3200000 | F10: 45147 | G10: 4350000
A11: 45146 | B11: Виливет двойка | C11: 60 | D11: 50000 | E11: =C11*D11 -> 3000000 | F11: 45148 | G11: 3700000 | I11: скидка
A12: 45147 | B12: Спортивка | C12: 80 | D12: 46000 | E12: =C12*D12 -> 3680000 | F12: 45149 | G12: 400000
A13: 45151 | B13: Айиқ полоска | C13: 10 | D13: 40000 | E13: =C13*D13 -> 400000 | F13: 45150 | G13: 2250000
A14: 45153 | B14: Янги двойка | C14: 54 | D14: 39000 | E14: =C14*D14 -> 2106000 | F14: 45151 | G14: 900000
A15: 45153 | B15: Виливет двойка | C15: 118 | D15: 50000 | E15: =C15*D15 -> 5900000 | F15: 45153 | G15: 7600000
A16: 45154 | B16: Янги двойка | C16: 4 | D16: 39000 | E16: =C16*D16 -> 156000 | F16: 45154 | G16: 2200000
A17: 45154 | B17: Виливет двойка | C17: 1 | D17: 50000 | E17: =C17*D17 -> 50000 | F17: 45155 | G17: 1130000
A18: 45158 | B18: Адидас спортивка | C18: 56 | D18: 45000 | E18: =C18*D18 -> 2520000 | F18: 45156 | G18: 2250000
A19: 45160 | B19: Адидас спортивка | C19: 110 | D19: 45000 | E19: =C19*D19 -> 4950000 | F19: 45157 | G19: 3250000
A20: 45160 | B20: Виливет двойка | C20: 48 | D20: 50000 | E20: =C20*D20 -> 2400000 | F20: 45158 | G20: 7750000
A21: 45161 | B21: Адидас спортивка | C21: 100 | D21: 45000 | E21: =C21*D21 -> 4500000 | F21: 45160 | G21: 5900000
A22: 45163 | B22: Адидас спортивка | C22: 16 | D22: 45000 | E22: =C22*D22 -> 720000 | F22: 45162 | G22: 2420000
A23: 45163 | B23: Виливет двойка | C23: 44 | D23: 50000 | E23: =C23*D23 -> 2200000 | F23: 45163 | G23: 4780000
... A28: 45167 | B28: Вил қиз ромашка | C28: 8 | D28: 38000 | E28: =C28*D28 -> 304000 | F28: 45169 | G28: 1950000
A29: 45167 | B29: Виливет двойка | C29: 104 | D29: 50000 | E29: =C29*D29 -> 5200000
A30: 45168 | B30: Адидас спортивка | C30: 28 | D30: 45000 | E30: =C30*D30 -> 1260000
E31: =C31*D31 -> 0
E32: =C32*D32 -> 0
E33: =C33*D33 -> 0
E34: =C34*D34 -> 0
E35: =C35*D35 -> 0
E36: =C36*D36 -> 0
E37: =C37*D37 -> 0
E38: =C38*D38 -> 0
E39: =C39*D39 -> 0
E40: =C40*D40 -> 0
E41: =C41*D41 -> 0
E42: =C42*D42 -> 0
... E133: =C133*D133 -> 0
E199: =SUM(E3:E198) -> 100046000 | G199: =SUM(G3:G198) -> 84934000

Sheet 2023 июл
A1: Реализация | F1: Касса | I1: Баланс
A2: Число | B2: Модел | C2: Сони | D2: Нархи | E2: Сумма | F2: Число | G2: Сумма | I2: Остатка сумма Бозорда
A3: Остатка сумма олдинги | E3: ='2023.3'!I3 -> 17766000 | F3: 45108 | G3: 4850000 | I3: =E199-G199 -> 37556000
A4: 45109 | B4: Ўғил кўйлак | C4: 196 | D4: 35000 | E4: =C4*D4 -> 6860000 | F4: 45109 | G4: 10165000 | I4: курс | J4: 11550
A5: 45111 | B5: Обадог | C5: 34 | D5: 35000 | E5: =C5*D5 -> 1190000 | F5: 45111 | G5: 7200000 | I5: =I3/J4 -> 3251.6017
A6: 45111 | B6: Ўғил кўйлак | C6: 110 | D6: 35000 | E6: =C6*D6 -> 3850000 | F6: 45112 | G6: 10850000 | I6: остатка товар. | J6: =ост.охири!F5 -> 35376000
A7: 45111 | B7: Қиз тройка | C7: 122 | D7: 42000 | E7: =C7*D7 -> 5124000 | F7: 45113 | G7: 9400000
A8: 45112 | B8: Қиз тройка | C8: 84 | D8: 42000 | E8: =C8*D8 -> 3528000 | F8: 45114 | G8: 12700000 | I8: Фарки | J8: =I3-J6 -> 2180000
A9: 45112 | B9: Обадог | C9: 94 | D9: 35000 | E9: =C9*D9 -> 3290000 | F9: 45115 | G9: 5550000
A10: 45113 | B10: Ўғил кўйлак | C10: 118 | D10: 35000 | E10: =C10*D10 -> 4130000 | F10: 45116 | G10: 1650000
A11: 45113 | B11: Обадог | C11: 100 | D11: 35000 | E11: =C11*D11 -> 3500000 | F11: 45118 | G11: 3200000 | I11: скидка
A12: 45113 | B12: Қиз тройка | C12: 80 | D12: 42000 | E12: =C12*D12 -> 3360000 | F12: 45119 | G12: 1300000
A13: 45114 | B13: Обадог | C13: 116 | D13: 35000 | E13: =C13*D13 -> 4060000 | F13: 45120 | G13: 1150000
A14: 45114 | B14: Қиз тройка | C14: 112 | D14: 42000 | E14: =C14*D14 -> 4704000 | F14: 45121 | G14: 500000
A15: 45114 | B15: Ўғил кўйлак | C15: 82 | D15: 35000 | E15: =C15*D15 -> 2870000 | F15: 45122 | G15: 574000
A16: 45115 | B16: Обадог | C16: 62 | D16: 35000 | E16: =C16*D16 -> 2170000 | F16: 45123 | G16: 2590000
A17: 45115 | B17: Қиз тройка | C17: 20 | D17: 42000 | E17: =C17*D17 -> 840000 | F17: 45125 | G17: 5600000
A18: 45115 | B18: Ўғил кўйлак | C18: 92 | D18: 35000 | E18: =C18*D18 -> 3220000 | F18: 45126 | G18: 4300000
A19: 45116 | B19: Қиз тройка | C19: 120 | D19: 42000 | E19: =C19*D19 -> 5040000 | F19: 45127 | G19: 2200000
A20: 45116 | B20: Обадог | C20: 50 | D20: 35000 | E20: =C20*D20 -> 1750000 | F20: 45128 | G20: 11100000
A21: 45116 | B21: Ўғил кўйлак | C21: 170 | D21: 35000 | E21: =C21*D21 -> 5950000 | F21: 45129 | G21: 1700000
A22: 45118 | B22: Панда полестр | C22: 30 | D22: 39000 | E22: =C22*D22 -> 1170000 | F22: 45130 | G22: 1480000 | H22: Зафар жиян
A23: 45118 | B23: Беар полестр | C23: 41 | D23: 38000 | E23: =C23*D23 -> 1558000 | F23: 45130 | G23: =900000+5117000 -> 6017000
A24: 45119 | B24: Обадог | C24: 126 | D24: 35000 | E24: =C24*D24 -> 4410000 | F24: 45132 | G24: 7000000 | H24: Возврат ёзги
A25: 45120 | B25: Қиз тройка | C25: 93 | D25: 42000 | E25: =C25*D25 -> 3906000 | F25: 45132 | G25: 600000
A26: 45125 | B26: Спортивка | C26: 38 | D26: 46000 | E26: =C26*D26 -> 1748000 | F26: 45134 | G26: 7000000
A27: 45125 | B27: Айиқ полоска | C27: 248 | D27: 40000 | E27: =C27*D27 -> 9920000 | F27: 45135 | G27: 3000000
A28: 45127 | B28: Спортивка | C28: 32 | D28: 46000 | E28: =C28*D28 -> 1472000 | F28: 45136 | G28: 750000
A29: 45127 | B29: Симба полестр | C29: 252 | D29: 39000 | E29: =C29*D29 -> 9828000 | F29: 45137 | G29: 300000
A30: 45128 | B30: Панда полестр | C30: 140 | D30: 39000 | E30: =C30*D30 -> 5460000
A31: 45128 | B31: Айиқ полоска | C31: 40 | D31: 40000 | E31: =C31*D31 -> 1600000
A32: 45128 | B32: Спортивка | C32: 52 | D32: 46000 | E32: =C32*D32 -> 2392000
A33: 45129 | B33: Айиқ полоска | C33: 244 | D33: 40000 | E33: =C33*D33 -> 9760000
A34: 45129 | B34: Спортивка | C34: 48 | D34: 46000 | E34: =C34*D34 -> 2208000
A35: 45130 | B35: Панда полестр | C35: 60 | D35: 39000 | E35: =C35*D35 -> 2340000
A36: 45130 | B36: Айиқ полоска | C36: 156 | D36: 40000 | E36: =C36*D36 -> 6240000
A37: 45132 | B37: Панда полестр | C37: 28 | D37: 39000 | E37: =C37*D37 -> 1092000
A38: 45133 | B38: Спортивка | C38: 88 | D38: 46000 | E38: =C38*D38 -> 4048000
A39: 45136 | B39: Айиқ полоска | C39: 124 | D39: 40000 | E39: =C39*D39 -> 4960000
A40: 45137 | B40: Айиқ полоска | C40: 58 | D40: 40000 | E40: =C40*D40 -> 2320000
...

Sheet Лист1
A1: =45+25+36.4+65+74.1+50+75+81+129+104+40+86+60+65+50+38.5+58+44.5+88+44+159+95+110.9+144+71.5+16.5+55+65+40+165+240+69.7+56.5+15+160+441.7+60+71+60+54.3+110+47+150+61+70+59.35+70+75+79+97+58.8+63+60+50+180+44+50+46+20+82+30+35+70+82+30+90+65+115.5+112+260+212.5+105+100+30+200+180+29+96.5+61.5+203+100+61.5+10+11+247+88+88+187+48.5+102+51+145+40.3+188+51.3+125+100+16+44.6+172.5+20+45.4+25+174+15+41 -> 9184.85 | B1: 1500 | C1: =A1*B1 -> 13777275 | D1: =C1/12250 -> 1124.6755
A3: =3+2.5+25.8+20.8+21.2+19.1+5.68+120+43.4+12.7+30.6+47+110+18.3+7.6+6.1+2+14.7+7.1+7.5+8.7+25+3.54+1.86+2.3+20.14+10+22.71+21.3+26.4+3+24.1+13+6.6+14.3+26+6.6+2.6+3.9+28+30+60+52+150+114.1+38+41.1+33+58.2+16.22+20.58 -> 1408.33 | B3: 0.2 | C3: =A3*B3 -> 281.666
D5: =C3+D1+23 -> 1429.3415

Sheet 2023.3
A1: Реализация | F1: Касса | I1: Баланс
A2: Число | B2: Модел | C2: Сони | D2: Нархи | E2: Сумма | F2: Число | G2: Сумма | I2: Остатка сумма Бозорда
A3: Остатка сумма олдинги | E3: ='2023.2'!I3 -> 16714000 | F3: 45078 | G3: 7900000 | I3: =E199-G199 -> 17766000
A4: 45078 | B4: Ўғил кўйлак | C4: 124 | D4: 35000 | E4: =C4*D4 -> 4340000 | F4: 45079 | G4: 7300000 | I4: курс | J4: 11400
A5: 45078 | B5: Обадог | C5: 78 | D5: 35000 | E5: =C5*D5 -> 2730000 | F5: 45080 | G5: =3950000+280000 -> 4230000 | I5: =I3/J4 -> 1558.4211
A6: 45079 | B6: Обадог | C6: 116 | D6: 35000 | E6: =C6*D6 -> 4060000 | F6: 45081 | G6: 7196000 | I6: остатка товар. | J6: =ост.охири!F5 -> 35376000
A7: 45080 | B7: София | C7: 16 | D7: 32500 | E7: =C7*D7 -> 520000 | F7: 45083 | G7: 10300000
A8: 45080 | B8: Ўғил кўйлак | C8: 100 | D8: 35000 | E8: =C8*D8 -> 3500000 | F8: 45084 | G8: 5170000 | I8: Фарки | J8: =I3-J6 -> -17610000
A9: 45080 | B9: Обадог | C9: 102 | D9: 35000 | E9: =C9*D9 -> 3570000 | F9: 45085 | G9: 7900000
A10: 45081 | B10: Ўғил кўйлак | C10: 188 | D10: 35000 | E10: =C10*D10 -> 6580000 | F10: 45086 | G10: 10150000
A11: 45083 | B11: София | C11: 160 | D11: 32500 | E11: =C11*D11 -> 5200000 | F11: 45087 | G11: 6600000 | I11: скидка
A12: 45083 | B12: Қиз тройка | C12: 80 | D12: 42000 | E12: =C12*D12 -> 3360000 | F12: 45088 | G12: 8202000
A13: 45084 | B13: Обадог | C13: 60 | D13: 35000 | E13: =C13*D13 -> 2100000 | F13: 45090 | G13: 11800000
A14: 45084 | B14: Қиз тройка | C14: 80 | D14: 42000 | E14: =C14*D14 -> 3360000 | F14: 45091 | G14: 7300000
A15: 45085 | B15: Ўғил кўйлак | C15: 52 | D15: 35000 | E15: =C15*D15 -> 1820000 | F15: 45092 | G15: 18000000
A16: 45085 | B16: Обадог | C16: 76 | D16: 35000 | E16: =C16*D16 -> 2660000 | F16: 45093 | G16: 9400000
A17: 45085 | B17: София | C17: 80 | D17: 32500 | E17: =C17*D17 -> 2600000 | F17: 45094 | G17: 4750000
A18: 45086 | B18: Ўғил кўйлак | C18: 78 | D18: 35000 | E18: =C18*D18 -> 2730000 | F18: 45095 | G18: 5685000
A19: 45086 | B19: Қиз тройка | C19: 58 | D19: 42000 | E19: =C19*D19 -> 2436000 | F19: 45097 | G19: 9700000
A20: 45086 | B20: Обадог | C20: 82 | D20: 35000 | E20: =C20*D20 -> 2870000 | F20: 45098 | G20: 13000000
A21: 45087 | B21: Ўғил кўйлак | C21: 54 | D21: 35000 | E21: =C21*D21 -> 1890000 | F21: 45099 | G21: 8500000
A22: 106 | B22: Обадог | C22: 81 | D22: 35000 | E22: =C22*D22 -> 2835000 | F22: 45100 | G22: 9100000
A23: 45087 | B23: Қиз тройка | C23: 58 | D23: 42000 | E23: =C23*D23 -> 2436000 | F23: 45101 | G23: 9500000
... A26: 45088 | B26: София | C26: 60 | D26: 32500 | E26: =C26*D26 -> 1950000 | F26: 45106 | G26: 4750000
A27: 45090 | B27: Ўғил кўйлак | C27: 96 | D27: 35000 | E27: =C27*D27 -> 3360000 | F27: 45107 | G27: =2900000+1725000 -> 4625000
A28: 45090 | B28: Қиз тройка | C28: 124 | D28: 42000 | E28: =C28*D28 -> 5208000
A29: 45090 | B29: Обадог | C29: 44 | D29: 35000 | E29: =C29*D29 -> 1540000
A30: 45090 | B30: София | C30: 42 | D30: 32500 | E30: =C30*D30 -> 1365000
A31: 45091 | B31: София | C31: 84 | D31: 32500 | E31: =C31*D31 -> 2730000
A32: 45091 | B32: Обадог | C32: 182 | D32: 35000 | E32: =C32*D32 -> 6370000
A33: 45092 | B33: Қиз тройка | C33: 72 | D33: 42000 | E33: =C33*D33 -> 3024000
A34: 45092 | B34: Ўғил кўйлак | C34: 100 | D34: 35000 | E34: =C34*D34 -> 3500000
A35: 45093 | B35: Обадог | C35: 158 | D35: 35000 | E35: =C35*D35 -> 5530000
A36: 45093 | B36: Ўғил кўйлак | C36: 60 | D36: 35000 | E36: =C36*D36 -> 2100000
A37: 45093 | B37: Қиз тройка | C37: 50 | D37: 42000 | E37: =C37*D37 -> 2100000
A38: 45094 | B38: Қиз тройка | C38: 106 | D38: 42000 | E38: =C38*D38 -> 4452000
A39: 45094 | B39: Ўғил кўйлак | C39: 106 | D39: 35000 | E39: =C39*D39 -> 3710000
... A62: 45104 | B62: Обадог | C62: 234 | D62: 35000 | E62: =C62*D62 -> 8190000
E63: =C63*D63 -> 0
E64: =C64*D64 -> 0
...

Sheet 2023.2
A1: Реализация | F1: Касса | I1: Баланс
A2: Число | B2: Модел | C2: Сони | D2: Нархи | E2: Сумма | F2: Число | G2: Сумма | I2: Остатка сумма Бозорда
A3: Остатка сумма олдинги | E3: ='2023.1'!I3 -> 9795000 | F3: 45048 | G3: 4250000 | I3: =E199-G199 -> 16714000
A4: 45048 | B4: Ўғил кўйлак | C4: 40 | D4: 35000 | E4: =C4*D4 -> 1400000 | F4: 45049 | G4: 3700000 | I4: курс | J4: 11400
A5: 45049 | B5: Қиз тройка | C5: 116 | D5: 42000 | E5: =C5*D5 -> 4872000 | F5: 45050 | G5: 6700000 | I5: =I3/J4 -> 1466.1404
A6: 45049 | B6: Ўғил кўйлак | C6: 96 | D6: 35000 | E6: =C6*D6 -> 3360000 | F6: 45051 | G6: 4450000 | I6: остатка товар. | J6: =ост.охири!F5 -> 35376000
A7: 45049 | B7: Симба лайкра | C7: 52 | D7: 32000 | E7: =C7*D7 -> 1664000 | F7: 45052 | G7: 5450000
A8: 45050 | B8: Симба лайкра | C8: 100 | D8: 32000 | E8: =C8*D8 -> 3200000 | F8: 45053 | G8: 6573000 | I8: Фарки | J8: =I3-J6 -> -18662000
A9: 45050 | B9: Топик гулли | C9: 64 | D9: 34000 | E9: =C9*D9 -> 2176000 | F9: 45055 | G9: 3800000
A10: 45051 | B10: Симба лайкра | C10: 60 | D10: 32000 | E10: =C10*D10 -> 1920000 | F10: 45056 | G10: 1232000
A11: 45051 | B11: Ўғил кўйлак | C11: 44 | D11: 35000 | E11: =C11*D11 -> 1540000 | F11: 45057 | G11: 4150000 | I11: скидка
A12: 45052 | B12: Ўғил кўйлак | C12: 110 | D12: 35000 | E12: =C12*D12 -> 3850000 | F12: 45058 | G12: 8350000
A13: 45052 | B13: Симба лайкра | C13: 44 | D13: 32000 | E13: =C13*D13 -> 1408000 | F13: 45059 | G13: 5000000
A14: 45052 | B14: Топик гулли | C14: 72 | D14: 34000 | E14: =C14*D14 -> 2448000 | F14: 45060 | G14: 6150000
A15: 45053 | B15: Қиз тройка | C15: 38 | D15: 42000 | E15: =C15*D15 -> 1596000 | F15: 45062 | G15: 5400000
A16: 45053 | B16: Ўғил кўйлак | C16: 102 | D16: 35000 | E16: =C16*D16 -> 3570000 | F16: 45063 | G16: 3800000
A17: 45055 | B17: Обадог | C17: 120 | D17: 35000 | E17: =C17*D17 -> 4200000 | F17: 45064 | G17: 3800000
A18: 44967 | B18: Ўғил кўйлак | C18: 164 | D18: 35000 | E18: =C18*D18 -> 5740000 | F18: 45065 | G18: 9500000
A19: 45057 | B19: Ўғил кўйлак | C19: 72 | D19: 35000 | E19: =C19*D19 -> 2520000 | F19: 45066 | G19: 3000000
A20: 45057 | B20: Обадог | C20: 50 | D20: 35000 | E20: =C20*D20 -> 1750000 | F20: 45067 | G20: 7933000
A21: 45058 | B21: Қиз тройка | C21: 66 | D21: 42000 | E21: =C21*D21 -> 2772000 | F21: 45069 | G21: 7000000
A22: 45059 | B22: Симба лайкра | C22: 190 | D22: 32000 | E22: =C22*D22 -> 6080000 | F22: 45070 | G22: 4700000
A23: 45059 | B23: Обадог | C23: 76 | D23: 35000 | E23: =C23*D23 -> 2660000 | F23: 45071 | G23: 9750000
A24: 45060 | B24: Ўғил кўйлак | C24: 104 | D24: 35000 | E24: =C24*D24 -> 3640000 | F24: 45072 | G24: 10400000
A25: 45060 | B25: Топик гулли | C25: 72 | D25: 34000 | E25: =C25*D25 -> 2448000 | F25: 45073 | G25: =200*11450 -> 2290000
A26: 45062 | B26: Симба лайкра | C26: 72 | D26: 32000 | E26: =C26*D26 -> 2304000 | F26: 45074 | G26: 4800000
A27: 45062 | B27: Ўғил кўйлак | C27: 104 | D27: 35000 | E27: =C27*D27 -> 3640000 | F27: 45076 | G27: 7665000
A28: 45062 | B28: Қиз тройка | C28: 124 | D28: 42000 | E28: =C28*D28 -> 5208000 | F28: 45077 | G28: 2550000
A29: 45063 | B29: Ўғил кўйлак | C29: 30 | D29: 35000 | E29: =C29*D29 -> 1050000
A30: 45064 | B30: Ўғил кўйлак | C30: 96 | D30: 35000 | E30: =C30*D30 -> 3360000
A31: 45065 | B31: Қиз тройка | C31: 80 | D31: 42000 | E31: =C31*D31 -> 3360000
A32: 45065 | B32: Обадог | C32: 98 | D32: 35000 | E32: =C32*D32 -> 3430000
A33: 45066 | B33: Ўғил кўйлак | C33: 68 | D33: 35000 | E33: =C33*D33 -> 2380000
A34: 45066 | B34: Обадог | C34: 98 | D34: 35000 | E34: =C34*D34 -> 3430000
A35: 45067 | B35: Обадог | C35: 106 | D35: 35000 | E35: =C35*D35 -> 3710000
A36: 45067 | B36: Қиз тройка | C36: 98 | D36: 42000 | E36: =C36*D36 -> 4116000
A37: 45069 | B37: Ўғил кўйлак | C37: 80 | D37: 35000 | E37: =C37*D37 -> 2800000
A38: 45069 | B38: Қиз тройка | C38: 60 | D38: 42000 | E38: =C38*D38 -> 2520000
A39: 45070 | B39: Ўғил кўйлак | C39: 80 | D39: 35000 | E39: =C39*D39 -> 2800000
A40: 45070 | B40: Обадог | C40: 94 | D40: 35000 | E40: =C40*D40 -> 3290000
...

Sheet 2023.1
A1: Реализация | F1: Касса | I1: Баланс
A2: Число | B2: Модел | C2: Сони | D2: Нархи | E2: Сумма | F2: Число | G2: Сумма | I2: Остатка сумма Бозорда
A3: Остатка сумма олдинги | E3: 20240000 | F3: 44978 | G3: 3300000 | I3: =E199-G199 -> 9795000
A4: 44978 | B4: Лоок ме | C4: 72 | D4: 40000 | E4: =C4*D4 -> 2880000 | F4: 44979 | G4: 4250000 | I4: курс | J4: 11400
A5: 44979 | B5: Мушук гул | C5: 64 | D5: 37000 | E5: =C5*D5 -> 2368000 | F5: 44980 | G5: 10000000 | I5: =I3/J4 -> 859.21053
A6: 44979 | B6: Беар чўнтак | C6: 70 | D6: 38000 | E6: =C6*D6 -> 2660000 | F6: 44981 | G6: 3700000 | I6: остатка товар. | J6: =ост.охири!F5 -> 35376000
A7: 44980 | B7: Беар чўнтак | C7: 62 | D7: 38000 | E7: =C7*D7 -> 2356000 | F7: 44982 | G7: 700000
A8: 44980 | B8: Мушук гул | C8: 120 | D8: 37000 | E8: =C8*D8 -> 4440000 | F8: 44983 | G8: 6454000 | I8: Фарки | J8: =I3-J6 -> -25581000
A9: 44980 | B9: Панда | C9: 180 | D9: 39000 | E9: =C9*D9 -> 7020000 | F9: 44985 | G9: 6100000
A10: 44981 | B10: Беар чўнтак | C10: 146 | D10: 38000 | E10: =C10*D10 -> 5548000 | F10: 44986 | G10: 2200000
A11: 44982 | B11: Беар чўнтак | C11: 54 | D11: 38000 | E11: =C11*D11 -> 2052000 | F11: 44987 | G11: 3760000 | I11: скидка
A12: 44983 | B12: Лоок ме | C12: 38 | D12: 40000 | E12: =C12*D12 -> 1520000 | F12: 44988 | G12: 850000
A13: 44983 | B13: Симба | C13: 84 | D13: 39000 | E13: =C13*D13 -> 3276000 | F13: 44989 | G13: 4700000
A14: 44985 | B14: Симба | C14: 104 | D14: 39000 | E14: =C14*D14 -> 4056000 | F14: 44990 | G14: 8913000
A15: 44986 | B15: Симба | C15: 118 | D15: 39000 | E15: =C15*D15 -> 4602000 | F15: 44992 | G15: 3000000
A16: 44987 | B16: Симба | C16: 50 | D16: 39000 | E16: =C16*D16 -> 1950000 | F16: 44993 | G16: 5550000
A17: 44989 | B17: Симба | C17: 80 | D17: 39000 | E17: =C17*D17 -> 3120000 | F17: 44994 | G17: 3600000
A18: 44989 | B18: Лоок ме | C18: 86 | D18: 40000 | E18: =C18*D18 -> 3440000 | F18: 44995 | G18: 3450000
A19: 44990 | B19: Лоок ме | C19: 10 | D19: 40000 | E19: =C19*D19 -> 400000 | F19: 44996 | G19: 1530000
A20: 44990 | B20: Симба | C20: 86 | D20: 39000 | E20: =C20*D20 -> 3354000 | F20: 44997 | G20: 3860000
A21: 44990 | B21: Атлас кўйлак | C21: 48 | D21: 37000 | E21: =C21*D21 -> 1776000 | F21: 44999 | G21: 1550000
A22: 44992 | B22: Симба | C22: 60 | D22: 39000 | E22: =C22*D22 -> 2340000 | F22: 45000 | G22: 3300000
A23: 44992 | B23: Атлас кўйлак | C23: 60 | D23: 37000 | E23: =C23*D23 -> 2220000 | F23: 45001 | G23: 4200000
... A31: 44999 | B31: Атлас кўйлак | C31: 60 | D31: 37000 | E31: =C31*D31 -> 2220000 | F31: 45011 | G31: 1100000
A32: 44999 | B32: Панда | C32: 84 | D32: 39000 | E32: =C32*D32 -> 3276000 | F32: 45013 | G32: =3373000+5228000 -> 8601000 | H32: Воз. Қалин | I32: 5228000
A33: 44999 | B33: Смайлик | C33: 80 | D33: 39000 | E33: =C33*D33 -> 3120000 | F33: 45014 | G33: =550000+3030000 -> 3580000
A34: 45000 | B34: Смайлик | C34: 50 | D34: 39000 | E34: =C34*D34 -> 1950000 | F34: 45015 | G34: 4200000
A35: 45000 | B35: Панда | C35: 84 | D35: 39000 | E35: =C35*D35 -> 3276000 | F35: 45016 | G35: =1900000+290000 -> 2190000
A36: 45001 | B36: Трусик кўйлак | C36: 96 | D36: 33000 | E36: =C36*D36 -> 3168000 | F36: 45017 | G36: 2380000
A37: 45003 | B37: Лион шортик | C37: 80 | D37: 28000 | E37: =C37*D37 -> 2240000
A38: 45003 | B38: Трусик кўйлак | C38: 60 | D38: 33000 | E38: =C38*D38 -> 1980000 | F38: 45018 | G38: 5330000
A39: 45004 | B39: Трусик кўйлак | C39: 32 | D39: 33000 | E39: =C39*D39 -> 1056000 | F39: 45020 | G39: 5850000
A40: 45006 | B40: Кўйлак куржували | C40: 46 | D40: 28000 | E40: =C40*D40 -> 1288000 | F40: 45021 | G40: 1250000
A41: 45007 | B41: Кўйлак куржували | C41: 78 | D41: 28000 | E41: =C41*D41 -> 2184000 | F41: 45022 | G41: 2750000
A42: 45008 | B42: Трусик кўйлак | C42: 30 | D42: 33000 | E42: =C42*D42 -> 990000 | F42: 45023 | G42: 1400000
A43: 45008 | B43: Кўйлак куржували | C43: 56 | D43: 28000 | E43: =C43*D43 -> 1568000 | F43: 45024
A44: 45009 | B44: Трусик кўйлак | C44: 60 | D44: 33000 | E44: =C44*D44 -> 1980000 | F44: 45025 | G44: 7512000
A45: 45011 | B45: Трусик кўйлак | C45: 110 | D45: 33000 | E45: =C45*D45 -> 3630000 | F45: 45027 | G45: 2010000
A46: 45011 | B46: Оқ кофта трусикли | C46: 72 | D46: 36000 | E46: =C46*D46 -> 2592000 | F46: 45028 | G46: 700000
A47: 45013 | B47: Трусик кўйлак | C47: 64 | D47: 33000 | E47: =C47*D47 -> 2112000 | F47: 45029 | G47: 13350000
...

Sheet 2022 Хособот 5
A1: Реализация | F1: Касса | I1: Баланс
A2: Число | B2: Модел | C2: Сони | D2: Нархи | E2: Сумма | F2: Число | G2: Сумма | I2: Остатка сумма Бозорда
A3: Остатка сумма олдинги | E3: ='2022 Хисобот 4'!I3 -> 14371000 | F3: 44761 | G3: 4820000 | I3: =E199-G199 -> 24230000
A4: 44761 | B4: Ўйинчоқ кўйлак | C4: 28 | D4: 28000 | E4: =C4*D4 -> 784000 | F4: 44762 | G4: 150000 | I4: курс | J4: 11000
B5: Сарафан | C5: 12 | D5: 28000 | E5: =C5*D5 -> 336000 | F5: 44763 | G5: 500000 | I5: =I3/J4 -> 2202.7273
B6: Қуло кўйлак | C6: 8 | D6: 23000 | E6: =C6*D6 -> 184000 | F6: 44764 | G6: 2800000 | I6: остатка товар. | J6: =ост.охири!F5 -> 35376000
A7: 44764 | B7: Беар мехли | C7: 128 | D7: 38000 | E7: =C7*D7 -> 4864000 | F7: 44765 | G7: 850000
A8: 44766 | B8: Беар мехли | C8: 202 | D8: 38000 | E8: =C8*D8 -> 7676000 | F8: 44766 | G8: 1010000 | I8: Фарки | J8: =I3-J6 -> -11146000
A9: 44768 | B9: Беар мехли | C9: 38 | D9: 38000 | E9: =C9*D9 -> 1444000 | F9: 44768 | G9: 1600000
A10: 44770 | B10: Беар мехли | C10: 100 | D10: 38000 | E10: =C10*D10 -> 3800000 | F10: 44769 | G10: 2130000
A11: 44771 | B11: Беар мехли | C11: 156 | D11: 38000 | E11: =C11*D11 -> 5928000 | F11: 44770 | G11: 6350000 | I11: скидка
A12: 44772 | B12: Мушук калла | C12: 62 | D12: 37000 | E12: =C12*D12 -> 2294000 | F12: 44771 | G12: 150000
A13: 44773 | B13: Мушук калла | C13: 148 | D13: 37000 | E13: =C13*D13 -> 5476000 | F13: 44772 | G13: 3800000
A14: 44775 | B14: Мушук калла | C14: 154 | D14: 37000 | E14: =C14*D14 -> 5698000 | F14: 44773 | G14: =3959000+2491000 -> 6450000 | H14: 3959000 | I14: Возврат сумма
A15: 44776 | B15: Беар мехли | C15: 128 | D15: 38000 | E15: =C15*D15 -> 4864000 | F15: 44775 | G15: 6300000
A16: 44778 | B16: Гул мушук | C16: 78 | D16: 37000 | E16: =C16*D16 -> 2886000 | F16: 44776 | G16: =13850000+1150000 -> 15000000
A17: 44779 | B17: Гул мушук | C17: 176 | D17: 37000 | E17: =C17*D17 -> 6512000 | F17: 44777 | G17: 1700000
A18: 44779 | B18: Беар мехли | C18: 30 | D18: 38000 | E18: =C18*D18 -> 1140000 | F18: 44778 | G18: 3550000
A19: 44780 | B19: Беар мехли | C19: 120 | D19: 38000 | E19: =C19*D19 -> 4560000 | F19: 44779 | G19: 926000
A20: 44780 | B20: Мушук калла | C20: 60 | D20: 37000 | E20: =C20*D20 -> 2220000 | F20: 44780 | G20: 8168000
A21: 44780 | B21: Гул мушук | C21: 32 | D21: 37000 | E21: =C21*D21 -> 1184000 | F21: 44782 | G21: 12115000
A22: 44780 | B22: Янги тигр | C22: 33 | D22: 38000 | E22: =C22*D22 -> 1254000 | F22: 44783 | G22: 6550000
A23: 44780 | B23: Крокодил | C23: 36 | D23: 35000 | E23: =C23*D23 -> 1260000 | F23: 44784 | G23: 600000
A24: 44780 | B24: Қиз пир пир | C24: 78 | D24: 38000 | E24: =C24*D24 -> 2964000 | F24: 44785 | G24: 5850000
A25: 44780 | B25: Ўйинчоқ двойка | C25: 64 | D25: 42000 | E25: =C25*D25 -> 2688000 | F25: 44786 | G25: 2000000
A26: 44782 | B26: Беар мехли | C26: 108 | D26: 38000 | E26: =C26*D26 -> 4104000 | F26: 44787 | G26: 5715000
A27: 44782 | B27: Мушук калла | C27: 120 | D27: 37000 | E27: =C27*D27 -> 4440000 | F27: 44789 | G27: 14000000
A28: 44783 | B28: Мушук калла | C28: 100 | D28: 37000 | E28: =C28*D28 -> 3700000 | F28: 44790 | G28: =1200000+9600000+2900000 -> 13700000
A29: 44783 | B29: Беар мехли | C29: 82 | D29: 38000 | E29: =C29*D29 -> 3116000 | F29: 44791 | G29: 13900000
A30: 44784 | B30: Мушук калла | C30: 62 | D30: 37000 | E30: =C30*D30 -> 2294000 | F30: 44792 | G30: 7775000
A31: 44785 | B31: Беар мехли | C31: 112 | D31: 38000 | E31: =C31*D31 -> 4256000 | F31: 44793 | G31: 7800000
A32: 44786 | B32: Беар мехли | C32: 74 | D32: 38000 | E32: =C32*D32 -> 2812000 | F32: 44794 | G32: 7007000
A33: 44787 | B33: Мушук калла | C33: 106 | D33: 37000 | E33: =C33*D33 -> 3922000 | F33: 44796 | G33: 3950000
A34: 44787 | B34: Гул мушук | C34: 38 | D34: 37000 | E34: =C34*D34 -> 1406000 | F34: 44797 | G34: 2850000
A35: 44787 | B35: Қиз пир пир | C35: 18 | D35: 38000 | E35: =C35*D35 -> 684000 | F35: 44798 | G35: 2200000
A36: 44789 | B36: Беар мехли | C36: 372 | D36: 38000 | E36: =C36*D36 -> 14136000 | F36: 44799 | G36: 10000000
A37: 44790 | B37: Мушук калла | C37: 60 | D37: 37000 | E37: =C37*D37 -> 2220000 | F37: 44800 | G37: 6200000
A38: 44791 | B38: Беар мехли | C38: 100 | D38: 38000 | E38: =C38*D38 -> 3800000 | F38: 44801 | G38: 12137000
A39: 44792 | B39: Мушук калла | C39: 66 | D39: 37000 | E39: =C39*D39 -> 2442000 | F39: 44803 | G39: 11000000
A40: 44792 | B40: Беар мехли | C40: 162 | D40: 38000 | E40: =C40*D40 -> 6156000 | F40: 44804 | G40: 3200000
...

Sheet 2022 Хисобот 4
A1: Реализация | F1: Касса | I1: Баланс
A2: Число | B2: Модел | C2: Сони | D2: Нархи | E2: Сумма | F2: Число | G2: Сумма | I2: Остатка сумма Бозорда
A3: Остатка сумма олдинги | E3: ='2021 Хисобот 3'!I3 -> 30649000 | F3: 44656 | G3: =170000+1400000 -> 1570000 | I3: =E199-G199 -> 14371000
A4: 44656 | B4: Жинси кўйлак | C4: 96 | D4: 28000 | E4: =C4*D4 -> 2688000 | F4: 44658 | G4: 3780000 | I4: курс | J4: 11200
A5: 44658 | B5: Ламка айиқ капалак | C5: 22 | D5: 22000 | E5: =C5*D5 -> 484000 | F5: 44659 | G5: 2800000 | I5: =I3/J4 -> 1283.125
A6: 44658 | B6: Ромашка тош | C6: 72 | D6: 27000 | E6: =C6*D6 -> 1944000 | F6: 44660 | G6: 6120000 | I6: остатка товар. | J6: =ост.охири!F5 -> 35376000
B7: Горох кўйлак | C7: 72 | D7: 27000 | E7: =C7*D7 -> 1944000 | F7: 44661 | G7: 24071000
B8: Тоника мушук | C8: 30 | D8: 18000 | E8: =C8*D8 -> 540000 | F8: 44661 | G8: 4216500 | I8: Фарки | J8: =I3-J6 -> -21005000
B9: Минни микки | C9: 12 | D9: 22000 | E9: =C9*D9 -> 264000 | F9: 44663 | G9: 6100000
B10: Майка ост | C10: 69 | D10: 12000 | E10: =C10*D10 -> 828000 | F10: 44664 | G10: 250000
B11: Майка шортик | C11: 48 | D11: 24000 | E11: =C11*D11 -> 1152000 | F11: 44665 | G11: 1450000 | I11: скидка
B12: Тарвуз кофта | C12: 171 | D12: 14500 | E12: =C12*D12 -> 2479500 | F12: 44666 | G12: 2425000
B13: Ловет двойка | C13: 6 | D13: 25000 | E13: =C13*D13 -> 150000 | F13: 44667 | G13: 700000
B14: Тройка қуён | C14: 6 | D14: 33000 | E14: =C14*D14 -> 198000 | F14: 44668 | G14: 7393000
B15: Крокодил двойка | C15: 10 | D15: 27000 | E15: =C15*D15 -> 270000 | F15: 44670 | G15: 4900000
B16: Двойка наклейка | C16: 66 | D16: 26000 | E16: =C16*D16 -> 1716000 | F16: 44671 | G16: 7865000
A17: 44659 | B17: Ромашка тош | C17: 42 | D17: 27000 | E17: =C17*D17 -> 1134000 | F17: 44672 | G17: 5165000
B18: Двойка наклейка | C18: 150 | D18: 26000 | E18: =C18*D18 -> 3900000 | F18: 44673 | G18: 8120000
A19: 44661 | B19: Кўйлак труси | C19: 74 | D19: 32000 | E19: =C19*D19 -> 2368000 | F19: 44674 | G19: 1000000
B20: Смайл двойка | C20: 40 | D20: 30000 | E20: =C20*D20 -> 1200000 | F20: 44675 | G20: =2604000-5000000 -> -2396000
B21: Тарвуз кофта | C21: 48 | D21: 14500 | E21: =C21*D21 -> 696000 | F21: 44677 | G21: 9500000
A22: 44663 | B22: Смайл двойка | C22: 124 | D22: 30000 | E22: =C22*D22 -> 3720000 | F22: 44678 | G22: 1730000
B23: Минни микки | C23: 34 | D23: 22000 | E23: =C23*D23 -> 748000 | F23: 44679 | G23: 3210000
A24: 44665 | B24: Смайл двойка | C24: 52 | D24: 30000 | E24: =C24*D24 -> 1560000 | F24: 44680 | G24: =670000+5000000 -> 5670000
A25: 44666 | B25: Кўйлак труси | C25: 28 | D25: 32000 | E25: =C25*D25 -> 896000 | F25: 44681 | G25: 1540000
B26: Двойка наклейка | C26: 220 | D26: 26000 | E26: =C26*D26 -> 5720000 | F26: 44682 | G26: 5916000
A27: 44667 | B27: Кўйлак труси | C27: 52 | D27: 32000 | E27: =C27*D27 -> 1664000 | F27: 44684 | G27: 4500000
B28: Двойка наклейка | C28: 54 | D28: 26000 | E28: =C28*D28 -> 1404000 | F28: 44686 | G28: 4200000
A29: 44668 | B29: Смайл двойка | C29: 98 | D29: 30000 | E29: =C29*D29 -> 2940000 | F29: 44687 | G29: 2950000
A30: 44670 | B30: Кўйлак труси | C30: 104 | D30: 32000 | E30: =C30*D30 -> 3328000 | F30: 44688 | G30: 2300000
B31: Смайл двойка | C31: 64 | D31: 30000 | E31: =C31*D31 -> 1920000 | F31: 44689 | G31: 7115000
A32: 44672 | B32: Смайл двойка | C32: 96 | D32: 30000 | E32: =C32*D32 -> 2880000 | F32: 44689 | G32: 244000 | H32: Орео разница
B33: Гипюр кўйлак | C33: 52 | D33: 30000 | E33: =C33*D33 -> 1560000 | F33: 44691 | G33: =685000+6240000 -> 6925000
A34: 44673 | B34: Гипюр кўйлак | C34: 80 | D34: 30000 | E34: =C34*D34 -> 2400000 | F34: 44692 | G34: 2500000
A35: 44674 | B35: Двойка наклейка | C35: 120 | D35: 26000 | E35: =C35*D35 -> 3120000 | F35: 44693 | G35: 3385000
B36: Смайл двойка | C36: 48 | D36: 30000 | E36: =C36*D36 -> 1440000 | F36: 44694 | G36: =2770000+90000 -> 2860000
A37: 44675 | B37: Двойка наклейка | C37: 100 | D37: 26000 | E37: =C37*D37 -> 2600000 | F37: 44695 | G37: 850000
B38: Гипюр кўйлак | C38: 80 | D38: 30000 | E38: =C38*D38 -> 2400000 | F38: 44696 | G38: 4736000
B39: Кўйлак труси | C39: 124 | D39: 32000 | E39: =C39*D39 -> 3968000 | F39: 44696 | G39: 66000 | H39: Жинси разница
B40: Смайл двойка | C40: 60 | D40: 30000 | E40: =C40*D40 -> 1800000 | F40: 44698 | G40: 2110000
...

Sheet Хисобот. 07
A1: Реализация | F1: Касса | I1: Баланс
A2: Число | B2: Модел | C2: Сони | D2: Нархи | E2: Сумма | F2: Число | G2: Сумма | I2: Остатка сумма Бозорда
A3: Остатка сумма олдинги | E3: 34082000 | F3: 44873 | G3: =110000+3400000 -> 3510000 | I3: =E199-G199 -> 20857000
A4: 44873 | B4: Палто сумка | C4: 40 | D4: 55000 | E4: =C4*D4 -> 2200000 | F4: 44874 | G4: 21900000 | I4: курс | J4: 11000
A5: 44874 | B5: Палто катак | C5: 32 | D5: 55000 | E5: =C5*D5 -> 1760000 | F5: 44875 | G5: 1050000 | I5: =I3/J4 -> 1896.0909
A6: 44875 | B6: Палто катак | C6: 28 | D6: 55000 | E6: =C6*D6 -> 1540000 | F6: 44876 | G6: 350000 | I6: остатка товар. | J6: =ост.охири!F5 -> 35376000
A7: 44875 | B7: Палто сумка | C7: 7 | D7: 55000 | E7: =C7*D7 -> 385000 | F7: 44877 | G7: 1700000
A8: 44876 | B8: Двойка чўнтак | C8: 68 | D8: 50000 | E8: =C8*D8 -> 3400000 | F8: 44878 | I8: Фарки | J8: =I3-J6 -> -14519000
A9: 44877 | B9: Двойка чўнтак | C9: 70 | D9: 50000 | E9: =C9*D9 -> 3500000
A10: 44878 | B10: Двойка чўнтак | C10: 50 | D10: 50000 | E10: =C10*D10 -> 2500000
E11: =C11*D11 -> 0 | I11: скидка
E12: =C12*D12 -> 0
E13: =C13*D13 -> 0
E14: =C14*D14 -> 0
E15: =C15*D15 -> 0
E16: =C16*D16 -> 0
E17: =C17*D17 -> 0
E18: =C18*D18 -> 0
E19: =C19*D19 -> 0
E20: =C20*D20 -> 0
E21: =C21*D21 -> 0
E22: =C22*D22 -> 0
E23: =C23*D23 -> 0
... E133: =C133*D133 -> 0
E199: =SUM(E3:E198) -> 49367000 | G199: =SUM(G3:G198) -> 28510000

Sheet 2021 Хисобот 3
A1: Реализация | F1: Касса | I1: Баланс
A2: Число | B2: Модел | C2: Сони | D2: Нархи | E2: Сумма | F2: Число | G2: Сумма | I2: Остатка сумма Бозорда
A3: Остатка сумма олдинги | E3: ='2021 Хисобот 2'!I3 -> 20721500 | F3: 44565 | G3: 300000 | I3: =E199-G199 -> 30649000
A4: 44565 | B4: тигр 3 ип | C4: 38 | D4: 42000 | E4: =C4*D4 -> 1596000 | F4: 44566 | G4: 1875000 | I4: курс | J4: 10850
A5: 44565 | B5: сайл 3 ип | C5: 30 | D5: 42000 | E5: =C5*D5 -> 1260000 | F5: 44567 | G5: 3425000 | I5: =I3/J4 -> 2824.7926
A6: 44565 | B6: смайлик футболка | C6: 36 | D6: 14000 | E6: =C6*D6 -> 504000 | F6: 44568 | G6: 15260000 | I6: остатка товар. | J6: =ост.охири!F5 -> 35376000
A7: 44566 | B7: тигр 3 ип | C7: 42 | D7: 42000 | E7: =C7*D7 -> 1764000 | F7: 44569 | G7: 2650000
A8: 44566 | B8: сайл 3 ип | C8: 80 | D8: 42000 | E8: =C8*D8 -> 3360000 | F8: 44570 | G8: 9288000 | H8: возврат | I8: Фарки | J8: =I3-J6 -> -4727000
A9: 44566 | B9: лоок полестр | C9: 135 | D9: 45000 | E9: =C9*D9 -> 6075000 | F9: 44570 | G9: 2528500
A10: 44567 | B10: сайл 3 ип | C10: 54 | D10: 42000 | E10: =C10*D10 -> 2268000
A11: 44567 | B11: тигр 3 ип | C11: 12 | D11: 42000 | E11: =C11*D11 -> 504000 | F11: 44572 | G11: 3700000 | I11: скидка
A12: 44567 | B12: сайл полестр | C12: =105+54 -> 159 | D12: 45000 | E12: =C12*D12 -> 7155000 | F12: 44573 | G12: 720000
A13: 44567 | B13: очки шапка пол. | C13: 12 | D13: 33500 | E13: =C13*D13 -> 402000 | F13: 44574 | G13: =7650000+800000 -> 8450000
A14: 44568 | B14: сайл 3 ип | C14: 37 | D14: 42000 | E14: =C14*D14 -> 1554000 | F14: 44575 | G14: 621000
A15: 44569 | B15: сайл 3 ип | C15: 126 | D15: 42000 | E15: =C15*D15 -> 5292000 | F15: 44576 | G15: 1662000
B16: * | E16: =C16*D16 -> 0 | F16: 44577 | G16: 2825000
A17: 44572 | B17: сайл полестр | C17: 60 | D17: 45000 | E17: =C17*D17 -> 2700000
A18: 44572 | B18: сайл 3 ип | C18: 60 | D18: 42000 | E18: =C18*D18 -> 2520000 | F18: 44580 | G18: 1550000
A19: 44572 | B19: лоок полестр | C19: 15 | D19: 45000 | E19: =C19*D19 -> 675000 | F19: 44581 | G19: 1250000
A20: 44573 | B20: сайл 3 ип | C20: 58 | D20: 42000 | E20: =C20*D20 -> 2436000 | F20: 44583 | G20: 1250000
A21: 44573 | B21: сайл полестр | C21: 54 | D21: 45000 | E21: =C21*D21 -> 2430000 | F21: 44584 | G21: 300000
A22: 44574 | B22: биг деар | C22: 120 | D22: 41000 | E22: =C22*D22 -> 4920000
A23: 44575 | B23: биг деар | C23: 177 | D23: 41000 | E23: =C23*D23 -> 7257000 | F23: 44586 | G23: 2700000
A24: 44576 | B24: биг деар | C24: 60 | D24: 41000 | E24: =C24*D24 -> 2460000 | F24: 44588 | G24: 6862000
A25: 44577 | B25: биг деар | C25: 45 | D25: 41000 | E25: =C25*D25 -> 1845000 | F25: 44590 | G25: 400000
A26: 44577 | B26: тигр 3 ип | C26: 60 | D26: 42000 | E26: =C26*D26 -> 2520000 | F26: 44591 | G26: 1240000
B27: 0 | E27: =C27*D27 -> 0
A28: 44580 | B28: кучук полестр | C28: 54 | D28: 41000 | E28: =C28*D28 -> 2214000 | F28: 44593 | G28: 500000
A29: 44581 | B29: кучук полестр | C29: 60 | D29: 41000 | E29: =C29*D29 -> 2460000 | F29: 44594 | G29: 1100000
A30: 44582 | B30: янги тигр полестр | C30: 45 | D30: 41000 | E30: =C30*D30 -> 1845000 | F30: 44595 | G30: 3415000
A31: 44583 | B31: янги тигр полестр | C31: 105 | D31: 41000 | E31: =C31*D31 -> 4305000 | F31: 44596 | G31: 284000
A32: 44583 | B32: кучук полестр | C32: 27 | D32: 41000 | E32: =C32*D32 -> 1107000 | F32: 44597 | G32: 1300000
